Workbook
Name jphalak: '[1]Dist. Rate'!$F$56
Name jphalak: '[2]Dist. Rate'!$F$56
Name mason: '[3]update Rate'!$F$6
Name sand: [4]District_Rate!$D$99

Sheet cover
A1: GOVERNMENT OF NEPAL
A2: RAINAS MUNICIPALITY
A3: OFFICE OF THE MUNICIPAL EXECUTIVE
A4: TINPIPLE,LAMJUNG
A13: RATE ANALYSIS
A14: [Civil Works ]
A36: DUDBC NORMS
A37: FISCAL YEAR : 2082/083

Sheet Summary
A1: =cover!A2 -> RAINAS MUNICIPALITY
A2: =cover!A3 -> OFFICE OF THE MUNICIPAL EXECUTIVE
A3: =cover!A4 -> TINPIPLE,LAMJUNG
A5: SUMMARY OF CIVIL RATE ANALYSIS
E6: F / Y : 2082/083
A7: S. No. | B7: N.C.N. | C7: DESCRIPTION OF WORKS | D7: UNIT | E7: RATE
E8: Dept | F8: Contract
C9: A - SITE PREPARATION WORK
A10: ='Rate Analysis'!A3 -> 1.01 | B10: =LOOKUP(A10,'Rate Analysis'!$A$3:$A$4887,'Rate Analysis'!$B$3:$B$4887) -> A1 (1-1A) | C10: =LOOKUP(A10,'Rate Analysis'!$A$3:$A$4887,'Rate Analysis'!$C$3:$C$4887) -> Cutting of tree, branch & log etc. (12-30 cm. girth above 1.00 mtr. From G.L.) with lead upto 15 mtr. | D10: =LOOKUP(A10,'Rate Analysis'!$A$3:$A$4887,'Rate Analysis'!$F$3:$F$4887) -> Nos. | E10: =LOOKUP(A10,'Rate Analysis'!$A$3:$A$4887,'Rate Analysis'!$G$3:$G$4887) -> 113.1 | F10: =LOOKUP(A10,'Rate Analysis'!$A$3:$A$4887,'Rate Analysis'!$H$3:$H$4887) -> 130.06
A11: ='Rate Analysis'!A11 -> 1.02 | B11: =LOOKUP(A11,'Rate Analysis'!$A$3:$A$4887,'Rate Analysis'!$B$3:$B$4887) -> A1 (1-1B) | C11: =LOOKUP(A11,'Rate Analysis'!$A$3:$A$4887,'Rate Analysis'!$C$3:$C$4887) -> Cutting of tree, branch & log etc. (31-60 cm. girth above 1.00 mtr. From G.L.) with lead upto 15 mtr. | D11: =LOOKUP(A11,'Rate Analysis'!$A$3:$A$4887,'Rate Analysis'!$F$3:$F$4887) -> Nos. | E11: =LOOKUP(A11,'Rate Analysis'!$A$3:$A$4887,'Rate Analysis'!$G$3:$G$4887) -> 339.3 | F11: =LOOKUP(A11,'Rate Analysis'!$A$3:$A$4887,'Rate Analysis'!$H$3:$H$4887) -> 390.19
A12: ='Rate Analysis'!A18 -> 1.03 | B12: =LOOKUP(A12,'Rate Analysis'!$A$3:$A$4887,'Rate Analysis'!$B$3:$B$4887) -> A1 (1-1C) | C12: =LOOKUP(A12,'Rate Analysis'!$A$3:$A$4887,'Rate Analysis'!$C$3:$C$4887) -> Cutting of tree, branch & log etc. (61-120 cm. girth above 1.00 mtr. From G.L.) with lead upto 15 mtr. | D12: =LOOKUP(A12,'Rate Analysis'!$A$3:$A$4887,'Rate Analysis'!$F$3:$F$4887) -> Nos. | E12: =LOOKUP(A12,'Rate Analysis'!$A$3:$A$4887,'Rate Analysis'!$G$3:$G$4887) -> 852.6 | F12: =LOOKUP(A12,'Rate Analysis'!$A$3:$A$4887,'Rate Analysis'!$H$3:$H$4887) -> 980.49
A13: ='Rate Analysis'!A25 -> 1.04 | B13: =LOOKUP(A13,'Rate Analysis'!$A$3:$A$4887,'Rate Analysis'!$B$3:$B$4887) -> A2 (1-2A) | C13: =LOOKUP(A13,'Rate Analysis'!$A$3:$A$4887,'Rate Analysis'!$C$3:$C$4887) -> Removing of tree root (12-30 cm. girth above 1.00 mtr. From G.L.) with lead upto 15 mtr. | D13: =LOOKUP(A13,'Rate Analysis'!$A$3:$A$4887,'Rate Analysis'!$F$3:$F$4887) -> Nos. | E13: =LOOKUP(A13,'Rate Analysis'!$A$3:$A$4887,'Rate Analysis'!$G$3:$G$4887) -> 348 | F13: =LOOKUP(A13,'Rate Analysis'!$A$3:$A$4887,'Rate Analysis'!$H$3:$H$4887) -> 400.2
A14: ='Rate Analysis'!A32 -> 1.05 | B14: =LOOKUP(A14,'Rate Analysis'!$A$3:$A$4887,'Rate Analysis'!$B$3:$B$4887) -> A2 (1-2B) | C14: =LOOKUP(A14,'Rate Analysis'!$A$3:$A$4887,'Rate Analysis'!$C$3:$C$4887) -> Removing of tree root (31-60 cm. girth above 1.00 mtr. From G.L.) with lead upto 15 mtr. | D14: =LOOKUP(A14,'Rate Analysis'!$A$3:$A$4887,'Rate Analysis'!$F$3:$F$4887) -> Nos. | E14: =LOOKUP(A14,'Rate Analysis'!$A$3:$A$4887,'Rate Analysis'!$G$3:$G$4887) -> 376.3 | F14: =LOOKUP(A14,'Rate Analysis'!$A$3:$A$4887,'Rate Analysis'!$H$3:$H$4887) -> 432.74
A15: ='Rate Analysis'!A39 -> 1.06 | B15: =LOOKUP(A15,'Rate Analysis'!$A$3:$A$4887,'Rate Analysis'!$B$3:$B$4887) -> A2 (1-2C) | C15: =LOOKUP(A15,'Rate Analysis'!$A$3:$A$4887,'Rate Analysis'!$C$3:$C$4887) -> Removing of tree root (61-120 cm. girth above 1.00 mtr. From G.L.) with lead upto 15 mtr. | D15: =LOOKUP(A15,'Rate Analysis'!$A$3:$A$4887,'Rate Analysis'!$F$3:$F$4887) -> Nos. | E15: =LOOKUP(A15,'Rate Analysis'!$A$3:$A$4887,'Rate Analysis'!$G$3:$G$4887) -> 2192.4 | F15: =LOOKUP(A15,'Rate Analysis'!$A$3:$A$4887,'Rate Analysis'!$H$3:$H$4887) -> 2521.26
A16: ='Rate Analysis'!A47 -> 1.07 | B16: =LOOKUP(A16,'Rate Analysis'!$A$3:$A$4887,'Rate Analysis'!$B$3:$B$4887) -> A3 | C16: =LOOKUP(A16,'Rate Analysis'!$A$3:$A$4887,'Rate Analysis'!$C$3:$C$4887) -> Cutting of grass, taking of root & cutting of raised soil & site leveling with all complete | D16: =LOOKUP(A16,'Rate Analysis'!$A$3:$A$4887,'Rate Analysis'!$F$3:$F$4887) -> Sqm. | E16: =LOOKUP(A16,'Rate Analysis'!$A$3:$A$4887,'Rate Analysis'!$G$3:$G$4887) -> 20.01 | F16: =LOOKUP(A16,'Rate Analysis'!$A$3:$A$4887,'Rate Analysis'!$H$3:$H$4887) -> 23.01
A17: ='Rate Analysis'!A55 -> 1.08 | B17: =LOOKUP(A17,'Rate Analysis'!$A$3:$A$4887,'Rate Analysis'!$B$3:$B$4887) -> A4 | C17: =LOOKUP(A17,'Rate Analysis'!$A$3:$A$4887,'Rate Analysis'!$C$3:$C$4887) -> Site Clearence cutting& removing the herbs, levelling the surface ETC before the construction work as per instruction & specification complete work | D17: =LOOKUP(A17,'Rate Analysis'!$A$3:$A$4887,'Rate Analysis'!$F$3:$F$4887) -> sqm. | E17: =LOOKUP(A17,'Rate Analysis'!$A$3:$A$4887,'Rate Analysis'!$G$3:$G$4887) -> 8.7 | F17: =LOOKUP(A17,'Rate Analysis'!$A$3:$A$4887,'Rate Analysis'!$H$3:$H$4887) -> 10
C19: B - EARTH & SAND WORK
A20: ='Rate Analysis'!A78 -> 2.01 | B20: =LOOKUP(A20,'Rate Analysis'!$A$3:$A$4887,'Rate Analysis'!$B$3:$B$4887) -> B1 (2-1) | C20: =LOOKUP(A20,'Rate Analysis'!$A$3:$A$4887,'Rate Analysis'!$C$3:$C$4887) -> Earthwork in excavation in medium type soils in foundation including 10m hauling distance and 1.5 m. lift manually all complete in approval of site engineer. | D20: =LOOKUP(A20,'Rate Analysis'!$A$3:$A$4887,'Rate Analysis'!$F$3:$F$4887) -> Cum. | E20: =LOOKUP(A20,'Rate Analysis'!$A$3:$A$4887,'Rate Analysis'!$G$3:$G$4887) -> 627.27 | F20: =LOOKUP(A20,'Rate Analysis'!$A$3:$A$4887,'Rate Analysis'!$H$3:$H$4887) -> 721.36
A21: ='Rate Analysis'!A86 -> 2.02 | B21: =LOOKUP(A21,'Rate Analysis'!$A$3:$A$4887,'Rate Analysis'!$B$3:$B$4887) -> B1 (2-2) | C21: =LOOKUP(A21,'Rate Analysis'!$A$3:$A$4887,'Rate Analysis'!$C$3:$C$4887) -> Earthwork in excavation in gravel type soils in foundation including 10m hauling distance and 1.5 m. lift manually all complete in approval of site engineer. | D21: =LOOKUP(A21,'Rate Analysis'!$A$3:$A$4887,'Rate Analysis'!$F$3:$F$4887) -> Cum. | E21: =LOOKUP(A21,'Rate Analysis'!$A$3:$A$4887,'Rate Analysis'!$G$3:$G$4887) -> 716.88 | F21: =LOOKUP(A21,'Rate Analysis'!$A$3:$A$4887,'Rate Analysis'!$H$3:$H$4887) -> 824.41
A22: ='Rate Analysis'!A95 -> 2.03 | B22: =LOOKUP(A22,'Rate Analysis'!$A$3:$A$4887,'Rate Analysis'!$B$3:$B$4887) -> B2 (2-25A) | C22: =LOOKUP(A22,'Rate Analysis'!$A$3:$A$4887,'Rate Analysis'!$C$3:$C$4887) -> Earth filling work in every 15-15 cm. layer with watering & lead upto 1o.00 mtr. & proper manual compaction. | D22: =LOOKUP(A22,'Rate Analysis'!$A$3:$A$4887,'Rate Analysis'!$F$3:$F$4887) -> Cum. | E22: =LOOKUP(A22,'Rate Analysis'!$A$3:$A$4887,'Rate Analysis'!$G$3:$G$4887) -> 435 | F22: =LOOKUP(A22,'Rate Analysis'!$A$3:$A$4887,'Rate Analysis'!$H$3:$H$4887) -> 500.25
A23: ='Rate Analysis'!A103 -> 2.04 | B23: =LOOKUP(A23,'Rate Analysis'!$A$3:$A$4887,'Rate Analysis'!$B$3:$B$4887) -> B2 (2-25A) | C23: =LOOKUP(A23,'Rate Analysis'!$A$3:$A$4887,'Rate Analysis'!$C$3:$C$4887) -> Earth filling (Earth transported from 5 Km. surrounding) work in every 15-15 cm. layer with watering & proper manual compaction. | D23: =LOOKUP(A23,'Rate Analysis'!$A$3:$A$4887,'Rate Analysis'!$F$3:$F$4887) -> Cum. | E23: =LOOKUP(A23,'Rate Analysis'!$A$3:$A$4887,'Rate Analysis'!$G$3:$G$4887) -> 1035 | F23: =LOOKUP(A23,'Rate Analysis'!$A$3:$A$4887,'Rate Analysis'!$H$3:$H$4887) -> 1190.25
A24: ='Rate Analysis'!A112 -> 2.05 | B24: =LOOKUP(A24,'Rate Analysis'!$A$3:$A$4887,'Rate Analysis'!$B$3:$B$4887) -> B2 (2-25B) | C24: =LOOKUP(A24,'Rate Analysis'!$A$3:$A$4887,'Rate Analysis'!$C$3:$C$4887) -> Earth filling work in every 15-15 cm. layer without watering & proper manual compaction. | D24: =LOOKUP(A24,'Rate Analysis'!$A$3:$A$4887,'Rate Analysis'!$F$3:$F$4887) -> Cum. | E24: =LOOKUP(A24,'Rate Analysis'!$A$3:$A$4887,'Rate Analysis'!$G$3:$G$4887) -> 217.5 | F24: =LOOKUP(A24,'Rate Analysis'!$A$3:$A$4887,'Rate Analysis'!$H$3:$H$4887) -> 250.12
A25: ='Rate Analysis'!A119 -> 2.06 | B25: =LOOKUP(A25,'Rate Analysis'!$A$3:$A$4887,'Rate Analysis'!$B$3:$B$4887) -> B2 (2-25B) | C25: =LOOKUP(A25,'Rate Analysis'!$A$3:$A$4887,'Rate Analysis'!$C$3:$C$4887) -> Earth filling (Earth transported from 5 Km. surrounding) work in every 15-15 cm. layer without watering & proper manual compaction. | D25: =LOOKUP(A25,'Rate Analysis'!$A$3:$A$4887,'Rate Analysis'!$F$3:$F$4887) -> Cum. | E25: =LOOKUP(A25,'Rate Analysis'!$A$3:$A$4887,'Rate Analysis'!$G$3:$G$4887) -> 737.5 | F25: =LOOKUP(A25,'Rate Analysis'!$A$3:$A$4887,'Rate Analysis'!$H$3:$H$4887) -> 848.12
A26: ='Rate Analysis'!A127 -> 2.07 | B26: =LOOKUP(A26,'Rate Analysis'!$A$3:$A$4887,'Rate Analysis'!$B$3:$B$4887) -> B3 (2-42A) | C26: =LOOKUP(A26,'Rate Analysis'!$A$3:$A$4887,'Rate Analysis'!$C$3:$C$4887) -> Sand filling work with watering & proper manual compaction. | D26: =LOOKUP(A26,'Rate Analysis'!$A$3:$A$4887,'Rate Analysis'!$F$3:$F$4887) -> Cum. | E26: =LOOKUP(A26,'Rate Analysis'!$A$3:$A$4887,'Rate Analysis'!$G$3:$G$4887) -> 3029 | F26: =LOOKUP(A26,'Rate Analysis'!$A$3:$A$4887,'Rate Analysis'!$H$3:$H$4887) -> 3483.35
A27: ='Rate Analysis'!A136 -> 2.08 | B27: =LOOKUP(A27,'Rate Analysis'!$A$3:$A$4887,'Rate Analysis'!$B$3:$B$4887) -> B3 (2-42B) | C27: =LOOKUP(A27,'Rate Analysis'!$A$3:$A$4887,'Rate Analysis'!$C$3:$C$4887) -> Gravel Sand mixed (agg-50% + sand 50%) filling work with proper manual compaction. | D27: =LOOKUP(A27,'Rate Analysis'!$A$3:$A$4887,'Rate Analysis'!$F$3:$F$4887) -> Cum. | E27: =LOOKUP(A27,'Rate Analysis'!$A$3:$A$4887,'Rate Analysis'!$G$3:$G$4887) -> 2225.5 | F27: =LOOKUP(A27,'Rate Analysis'!$A$3:$A$4887,'Rate Analysis'!$H$3:$H$4887) -> 2559.32
A28: ='Rate Analysis'!A151 -> 2.09 | B28: =LOOKUP(A28,'Rate Analysis'!$A$3:$A$4887,'Rate Analysis'!$B$3:$B$4887) -> B4 (2-34) | C28: =LOOKUP(A28,'Rate Analysis'!$A$3:$A$4887,'Rate Analysis'!$C$3:$C$4887) -> Pumping of water from foundation or trench | D28: =LOOKUP(A28,'Rate Analysis'!$A$3:$A$4887,'Rate Analysis'!$F$3:$F$4887) -> Hrs | E28: ='Rate Analysis'!G151 -> 50.714 | F28: =E28*1.15 -> 58.3211
A29: ='Rate Analysis'!A158 -> 2.11 | B29: =LOOKUP(A29,[5]Analysis!$A$3:$A$6312,[5]Analysis!$B$3:$B$6312) -> B5 | C29: =LOOKUP(A29,[5]Analysis!$A$3:$A$6312,[5]Analysis!$C$3:$C$6312) -> Compaction of filled earth by 8-10 M.T. roller in 20/20 cm layer | D29: =LOOKUP(A29,[5]Analysis!$A$3:$A$6312,[5]Analysis!$F$3:$F$6312) -> Cum. | E29: ='Rate Analysis'!G158 -> 26.18 | F29: ='Rate Analysis'!H158 -> 30.11
A30: ='Rate Analysis'!A164 -> 2.12 | B30: =LOOKUP(A30,[5]Analysis!$A$3:$A$6312,[5]Analysis!$B$3:$B$6312) -> B5 | C30: =LOOKUP(A30,[5]Analysis!$A$3:$A$6312,[5]Analysis!$C$3:$C$6312) -> Compaction of filled earth by 1.00 M.T. Hand roller in 20/20 cm layer | D30: =LOOKUP(A30,[5]Analysis!$A$3:$A$6312,[5]Analysis!$F$3:$F$6312) -> Cum. | E30: ='Rate Analysis'!G164 -> 5.01 | F30: ='Rate Analysis'!H164 -> 5.76
A31: ='Rate Analysis'!A172 -> 2.13 | B31: =LOOKUP(A31,[5]Analysis!$A$3:$A$6312,[5]Analysis!$B$3:$B$6312) -> B7 | C31: =LOOKUP(A31,[5]Analysis!$A$3:$A$6312,[5]Analysis!$C$3:$C$6312) -> Earth work excavation in foundation in SOFT SOIL(USED 0.80 CUM. CAPACITY HYDROLIC EXCAVATOR) | D31: =LOOKUP(A31,[5]Analysis!$A$3:$A$6312,[5]Analysis!$F$3:$F$6312) -> Cum. | E31: ='Rate Analysis'!G172 -> 41.65 | F31: ='Rate Analysis'!H172 -> 47.89
A32: ='Rate Analysis'!A180 -> 2.14 | B32: =LOOKUP(A32,[5]Analysis!$A$3:$A$6312,[5]Analysis!$B$3:$B$6312) -> B7 | C32: =LOOKUP(A32,[5]Analysis!$A$3:$A$6312,[5]Analysis!$C$3:$C$6312) -> Earth work excavation in foundation in HARD SOIL USED 0.80 CUM. CAPACITY HYDROLIC EXCAVATOR) | D32: =LOOKUP(A32,[5]Analysis!$A$3:$A$6312,[5]Analysis!$F$3:$F$6312) -> Cum. | E32: ='Rate Analysis'!G180 -> 50.06 | F32: ='Rate Analysis'!H180 -> 57.56
A33: ='Rate Analysis'!A188 -> 2.15 | B33: =LOOKUP(A33,[5]Analysis!$A$3:$A$6312,[5]Analysis!$B$3:$B$6312) -> B7 | C33: =LOOKUP(A33,[5]Analysis!$A$3:$A$6312,[5]Analysis!$C$3:$C$6312) -> Earth work excavation in foundation in HARD SOIL USED 0.80 CUM. CAPACITY HYDROLIC EXCAVATOR) | D33: =LOOKUP(A33,[5]Analysis!$A$3:$A$6312,[5]Analysis!$F$3:$F$6312) -> Cum. | E33: ='Rate Analysis'!G188 -> 50.06 | F33: ='Rate Analysis'!H188 -> 57.56
A34: ='Rate Analysis'!A196 -> 2.16 | B34: =LOOKUP(A34,[5]Analysis!$A$3:$A$6312,[5]Analysis!$B$3:$B$6312) -> B7 | C34: =LOOKUP(A34,[5]Analysis!$A$3:$A$6312,[5]Analysis!$C$3:$C$6312) -> Earth work excavation in foundation in SOFT SOILUsed 1.32Cum capecity hydrolic excavator | D34: =LOOKUP(A34,[5]Analysis!$A$3:$A$6312,[5]Analysis!$F$3:$F$6312) -> Cum. | E34: ='Rate Analysis'!G196 -> 27.63 | F34: ='Rate Analysis'!H196 -> 31.77
A35: ='Rate Analysis'!A204 -> 2.17 | B35: ='Rate Analysis'!B204 -> B7 | C35: ='Rate Analysis'!C204 -> Earth work excavation in foundation in HARD SOIL Used 1.32Cum capecity Hydraulic excavator | D35: ='Rate Analysis'!F204 -> Cum. | E35: ='Rate Analysis'!G204 -> 33.64 | F35: ='Rate Analysis'!H204 -> 38.68
C36: C - MASONRY WORK
A37: ='Rate Analysis'!A213 -> 3.01 | B37: =LOOKUP(A37,'Rate Analysis'!$A$3:$A$4887,'Rate Analysis'!$B$3:$B$4887) -> C2(5-1-B1 & 5-2A) | C37: Good quality local chimney made Brickwork in 1:3 Cement : sand mortar up to Ground floor in perfect line level finish including supply of materials, wetting the bricks, racking the joints and curing the work for at least 7 days all complete as per approved drawing, Specification and instruction of site engineer. | D37: =LOOKUP(A37,'Rate Analysis'!$A$3:$A$4887,'Rate Analysis'!$F$3:$F$4887) -> Cum. | E37: =LOOKUP(A37,'Rate Analysis'!$A$3:$A$4887,'Rate Analysis'!$G$3:$G$4887) -> 13587.22 | F37: =LOOKUP(A37,'Rate Analysis'!$A$3:$A$4887,'Rate Analysis'!$H$3:$H$4887) -> 15625.3
A38: ='Rate Analysis'!A227 -> 3.02 | B38: =LOOKUP(A38,'Rate Analysis'!$A$3:$A$4887,'Rate Analysis'!$B$3:$B$4887) -> C2(5-1-B1 & 5-2B) | C38: Good quality local chimney made Brickwork in 1:3 Cement : sand mortar up to FIRST floor in perfect line level finish including supply of materials, wetting the bricks, racking the joints and curing the work for at least 7 days all complete as per approved drawing, Specification and instruction of site engineer. | D38: =LOOKUP(A38,'Rate Analysis'!$A$3:$A$4887,'Rate Analysis'!$F$3:$F$4887) -> Cum. | E38: =LOOKUP(A38,'Rate Analysis'!$A$3:$A$4887,'Rate Analysis'!$G$3:$G$4887) -> 14035.27 | F38: =LOOKUP(A38,'Rate Analysis'!$A$3:$A$4887,'Rate Analysis'!$H$3:$H$4887) -> 16140.56
A39: ='Rate Analysis'!A241 -> 3.03 | B39: =LOOKUP(A39,'Rate Analysis'!$A$3:$A$4887,'Rate Analysis'!$B$3:$B$4887) -> C2(5-1-B1 & 5-2B) | C39: Good quality local chimney made Brickwork in 1:3 Cement : sand mortar up to second floor in perfect line level finish including supply of materials, wetting the bricks, racking the joints and curing the work for at least 7 days all complete as per approved drawing, Specification and instruction of site engineer. | D39: =LOOKUP(A39,'Rate Analysis'!$A$3:$A$4887,'Rate Analysis'!$F$3:$F$4887) -> Cum. | E39: =LOOKUP(A39,'Rate Analysis'!$A$3:$A$4887,'Rate Analysis'!$G$3:$G$4887) -> 14662.54 | F39: =LOOKUP(A39,'Rate Analysis'!$A$3:$A$4887,'Rate Analysis'!$H$3:$H$4887) -> 16861.92
A40: ='Rate Analysis'!A255 -> 3.04 | B40: =LOOKUP(A40,'Rate Analysis'!$A$3:$A$4887,'Rate Analysis'!$B$3:$B$4887) -> C2( 5-1-B2 & 5-2A) | C40: Good quality local chimney made Brickwork in 1:4 Cement : sand mortar up to Ground floor in perfect line level finish including supply of materials, wetting the bricks, racking the joints and curing the work for at least 7 days all complete as per approved drawing, Specification and instruction of site engineer. | D40: =LOOKUP(A40,'Rate Analysis'!$A$3:$A$4887,'Rate Analysis'!$F$3:$F$4887) -> Cum. | E40: =LOOKUP(A40,'Rate Analysis'!$A$3:$A$4887,'Rate Analysis'!$G$3:$G$4887) -> 13189.22 | F40: =LOOKUP(A40,'Rate Analysis'!$A$3:$A$4887,'Rate Analysis'!$H$3:$H$4887) -> 15167.6
A41: ='Rate Analysis'!A269 -> 3.05 | B41: =LOOKUP(A41,'Rate Analysis'!$A$3:$A$4887,'Rate Analysis'!$B$3:$B$4887) -> C25-1-B2 & 5-2B) | C41: Good quality local chimney made Brickwork in 1:4 Cement : sand mortar up to FIRST floor in perfect line level finish including supply of materials, wetting the bricks, racking the joints and curing the work for at least 7 days all complete as per approved drawing, Specification and instruction of site engineer. | D41: =LOOKUP(A41,'Rate Analysis'!$A$3:$A$4887,'Rate Analysis'!$F$3:$F$4887) -> Cum. | E41: =LOOKUP(A41,'Rate Analysis'!$A$3:$A$4887,'Rate Analysis'!$G$3:$G$4887) -> 13637.27 | F41: =LOOKUP(A41,'Rate Analysis'!$A$3:$A$4887,'Rate Analysis'!$H$3:$H$4887) -> 15682.86
A42: ='Rate Analysis'!A282 -> 3.06 | B42: =LOOKUP(A42,'Rate Analysis'!$A$3:$A$4887,'Rate Analysis'!$B$3:$B$4887) -> C2(5-1-B2 & 5-2B) | C42: Good quality local chimney made Brickwork in 1:4 Cement : sand mortar up to second floor in perfect line level finish including supply of materials, wetting the bricks, racking the joints and curing the work for at least 7 days all complete as per approved drawing, Specification and instruction of site engineer. | D42: =LOOKUP(A42,'Rate Analysis'!$A$3:$A$4887,'Rate Analysis'!$F$3:$F$4887) -> Cum. | E42: =LOOKUP(A42,'Rate Analysis'!$A$3:$A$4887,'Rate Analysis'!$G$3:$G$4887) -> 14264.54 | F42: =LOOKUP(A42,'Rate Analysis'!$A$3:$A$4887,'Rate Analysis'!$H$3:$H$4887) -> 16404.22
...

Sheet Basic Rate
A1: =cover!A1 -> GOVERNMENT OF NEPAL
A2: =cover!A2 -> RAINAS MUNICIPALITY
A3: =cover!A3 -> OFFICE OF THE MUNICIPAL EXECUTIVE
A4: =cover!A4 -> TINPIPLE,LAMJUNG
A5: =cover!A5 -> 0
A6: BASIC LABOUR & MATERIAL RATE
A7: DISTRICT : BARA | G7: F / Y : 2082/083
A8: S.No. | B8: Description | C8: Unit | D8: District Rate | E8: Transportation @ 3 % | F8: Rate | G8: Remarks | H8: District Rate Page no & S.N
A9: 1 | B9: Aggregate >10 mm-Crushed | C9: Cum. | D9: 2430 | F9: =D9+E9 -> 2430 | H9: 4-164
A10: 2 | B10: Aggregate >10 mm-River bed | C10: Cum. | D10: 1830 | F10: =D10+E10 -> 1830 | H10: 4-168
A11: 3 | B11: Aggregate 10 mm-Crushed | C11: Cum. | D11: 2800 | F11: =D11+E11 -> 2800 | H11: =H9 -> 4-164
A12: 4 | B12: Aggregate 10 mm-River bed | C12: Cum. | D12: 1910 | F12: =D12+E12 -> 1910 | H12: 4-168
A13: 5 | B13: Aggregate 12 mm-Crushed | C13: Cum. | D13: =D9 -> 2430 | F13: =D13+E13 -> 2430 | H13: 4-164
A14: 6 | B14: Aggregate 12 mm-River bed | C14: Cum. | D14: =D10 -> 1830 | F14: =D14+E14 -> 1830 | H14: 4-168
A15: 7 | B15: Aggregate 20 mm-Crushed | C15: Cum. | D15: 2430 | F15: =D15+E15 -> 2430 | H15: 4-164
A16: 8 | B16: Aggregate 20 mm-River bed | C16: Cum. | D16: 1830 | F16: =D16+E16 -> 1830 | H16: 4-168
A17: 9 | B17: Aggregate 40 mm-Crushed | C17: Cum. | D17: 2135 | F17: =D17+E17 -> 2135 | H17: 4-164
A18: 10 | B18: Aggregate 40 mm-River bed | C18: Cum. | D18: 1830 | F18: =D18+E18 -> 1830 | H18: 4-168
A19: 11 | B19: Aluminium paint | C19: Ltr. | D19: 561 | F19: =D19+E19 -> 561 | H19: 13-494
A20: 12 | B20: Asbestos cement ridge cover | C20: Rmtr. | D20: =D21/0.6 -> 866.66667 | F20: =D20+E20 -> 866.66667 | G20: ridge width 0.6 m
A21: 13 | B21: Asbestos cement sheet | C21: Sqm. | D21: 520 | F21: =D21+E21 -> 520 | H21: 6-270
A22: 14 | B22: ASO Joint Tape laying Work. | C22: Rmtr.
A23: 15 | B23: Assistant lab equipment with agar | C23: Hour | D23: .
A24: 16 | B24: Bamboo | C24: No. | D24: 263 | F24: =D24+E24 -> 263 | H24: 3-104
A25: 17 | B25: Barbed wire 12 Bwg.(7m per Kg) | C25: Rmtr. | D25: =133/7 -> 19 | F25: =D25+E25 -> 19 | G25: 133 per kg | H25: 7-262
A26: 18 | B26: Barbed wire 14 Bwg.(7m per Kg) | C26: Rmtr. | D26: =133/7 -> 19 | F26: =D26+E26 -> 19 | G26: 134 per kg | H26: 7-263
A27: 19 | B27: Bhush | C27: Kg.
A28: 20 | B28: Binding wire | C28: Kg. | D28: 140 | F28: =D28+E28 -> 140 | H28: 5-212
A29: 21 | B29: Bitumen (VG 30) | C29: Kg. | D29: 110.7 | F29: =D29+E29 -> 110.7
A30: 22 | B30: Bitumen paint | C30: Ltr. | D30: 173 | F30: =D30+E30 -> 173 | H30: 13-507
A31: 23 | B31: Bitumen washer | C31: Nos. | D31: 0.63 | F31: =D31+E31 -> 0.63 | H31: 7-300
A32: 24 | B32: Brick Aggregate | C32: Cum. | D32: 2500 | F32: =D32+E32 -> 2500 | H32: 3-109
A33: 25 | B33: Brick | C33: Nos. | D33: 13 | F33: =D33+E33 -> 13 | H33: 3-105
A34: 27 | B34: Carborundam Stone(Sharpenning Stone) | C34: Nos. | D34: 254 | F34: =D34+E34 -> 254 | H34: 5-181
A35: 28 | B35: Cement | C35: MT | D35: 14000 | F35: =D35+E35 -> 14000 | H35: 5-201
A36: 29 | B36: Cement primer | C36: Ltr. | H36: ***
B37: Cement tile | C37: No. | D37: 18 | F37: =D37+E37 -> 18 | H37: 7-309
A38: 31 | B38: Cement tile ridge cover | C38: No. | D38: 20 | F38: =D38+E38 -> 20 | H38: 7-310
A39: 32 | B39: Stainless Steel 50mm dia Handrail pipe,in between 20 mm dia s.s. pipe 3 line ,40 mm vertical post 8/8 ft apart and 75 mm baluster pipe with 900 mm height all complete | C39: Rmtr. | D39: =1600*3.28 -> 5248 | F39: =D39+E39 -> 5248 | H39: 6-246
A40: 33 | B40: CGI Ridge Cover colour 26 (h) | C40: Rmtr. | D40: =(3257/12)/18*4*3.28 -> 197.83259 | F40: =D40 -> 197.83259 | G40: width=0.60m | H40: 7-256
...

Sheet Rate Analysis
A1: A - SITE PREPARATION WORK
A3: 1.01 | B3: A1 (1-1A) | C3: Cutting of tree, branch & log etc. (12-30 cm. girth above 1.00 mtr. From G.L.) with lead upto 15 mtr. | F3: Nos. | G3: =G6 -> 113.1 | H3: =G8 -> 130.06
B4: Resources | C4: Level/Type | D4: Quantity | E4: Unit | F4: Rate | G4: Amount | H4: Remarks
B5: Labour | C5: Unskilled | D5: 0.13 | E5: Nos. | F5: ='LABOUR 2082083'!F3 -> 870 | G5: =TRUNC(D5*F5,2) -> 113.1
B6: Rate analysis for : 1.00 No. | D6: Total | G6: =SUM(G5:G5) -> 113.1
D7: 15 % Contractor overhead | G7: =TRUNC(G6*15%,2) -> 16.96
D8: Grand Total | G8: =SUM(G6:G7) -> 130.06
A11: 1.02 | B11: A1 (1-1B) | C11: Cutting of tree, branch & log etc. (31-60 cm. girth above 1.00 mtr. From G.L.) with lead upto 15 mtr. | F11: Nos. | G11: =G14 -> 339.3 | H11: =G16 -> 390.19
B12: Resources | C12: Level/Type | D12: Quantity | E12: Unit | F12: Rate | G12: Amount | H12: Remarks
B13: Labour | C13: Unskilled | D13: 0.39 | E13: Nos. | F13: 870 | G13: =TRUNC(D13*F13,2) -> 339.3
B14: Rate analysis for : 1.00 No. | D14: Total | G14: =SUM(G13:G13) -> 339.3
D15: 15 % Contractor overhead | G15: =TRUNC(G14*15%,2) -> 50.89
D16: Grand Total | G16: =SUM(G14:G15) -> 390.19
A18: 1.03 | B18: A1 (1-1C) | C18: Cutting of tree, branch & log etc. (61-120 cm. girth above 1.00 mtr. From G.L.) with lead upto 15 mtr. | F18: Nos. | G18: =G21 -> 852.6 | H18: =G23 -> 980.49
B19: Resources | C19: Level/Type | D19: Quantity | E19: Unit | F19: Rate | G19: Amount | H19: Remarks
B20: Labour | C20: Unskilled | D20: 0.98 | E20: Nos. | F20: ='LABOUR 2082083'!F3 -> 870 | G20: =TRUNC(D20*F20,2) -> 852.6
B21: Rate analysis for : 1.00 No. | D21: Total | G21: =SUM(G20:G20) -> 852.6
D22: 15 % Contractor overhead | G22: =TRUNC(G21*15%,2) -> 127.89
D23: Grand Total | G23: =SUM(G21:G22) -> 980.49
A25: 1.04 | B25: A2 (1-2A) | C25: Removing of tree root (12-30 cm. girth above 1.00 mtr. From G.L.) with lead upto 15 mtr. | F25: Nos. | G25: =G28 -> 348 | H25: =G30 -> 400.2
B26: Resources | C26: Level/Type | D26: Quantity | E26: Unit | F26: Rate | G26: Amount | H26: Remarks
B27: Labour | C27: Unskilled | D27: 0.4 | E27: Nos. | F27: ='LABOUR 2082083'!F3 -> 870 | G27: =TRUNC(D27*F27,2) -> 348
B28: Rate analysis for : 1.00 No. | D28: Total | G28: =SUM(G27:G27) -> 348
D29: 15 % Contractor overhead | G29: =TRUNC(G28*15%,2) -> 52.2
D30: Grand Total | G30: =SUM(G28:G29) -> 400.2
A32: 1.05 | B32: A2 (1-2B) | C32: Removing of tree root (31-60 cm. girth above 1.00 mtr. From G.L.) with lead upto 15 mtr. | F32: Nos. | G32: =G35 -> 376.3 | H32: =G37 -> 432.74
B33: Resources | C33: Level/Type | D33: Quantity | E33: Unit | F33: Rate | G33: Amount | H33: Remarks
B34: Labour | C34: Unskilled | D34: 0.53 | E34: Nos. | F34: ='LABOUR 2082083'!F11 -> 710 | G34: =TRUNC(D34*F34,2) -> 376.3
B35: Rate analysis for : 1.00 No. | D35: Total | G35: =SUM(G34:G34) -> 376.3
D36: 15 % Contractor overhead | G36: =TRUNC(G35*15%,2) -> 56.44
D37: Grand Total | G37: =SUM(G35:G36) -> 432.74
A39: 1.06 | B39: A2 (1-2C) | C39: Removing of tree root (61-120 cm. girth above 1.00 mtr. From G.L.) with lead upto 15 mtr. | F39: Nos. | G39: =G42 -> 2192.4 | H39: =G44 -> 2521.26
B40: Resources | C40: Level/Type | D40: Quantity | E40: Unit | F40: Rate | G40: Amount | H40: Remarks
B41: Labour | C41: Unskilled | D41: 2.52 | E41: Nos. | F41: ='LABOUR 2082083'!F3 -> 870 | G41: =TRUNC(D41*F41,2) -> 2192.4
B42: Rate analysis for : 1.00 No. | D42: Total | G42: =SUM(G41:G41) -> 2192.4
D43: 15 % Contractor overhead | G43: =TRUNC(G42*15%,2) -> 328.86
D44: Grand Total | G44: =SUM(G42:G43) -> 2521.26
A47: 1.07 | B47: A3 | C47: Cutting of grass, taking of root & cutting of raised soil & site leveling with all complete | F47: Sqm. | G47: =TRUNC(G50/10,2) -> 20.01 | H47: =TRUNC(G52/10,2) -> 23.01
B48: Resources | C48: Level/Type | D48: Quantity | E48: Unit | F48: Rate | G48: Amount | H48: Remarks
B49: Labour | C49: Unskilled | D49: 0.23 | E49: Nos. | F49: ='LABOUR 2082083'!F3 -> 870 | G49: =TRUNC(D49*F49,2) -> 200.1
...

Sheet LABOUR 2082083
A2: सि.न | B2: कामदारको विवरण | C2: इकाई | F2: आ.व.०८२०८३ | G2: कैफियत
A3: 1 | B3: HofdL | C3: b}lgs | D3: 600 | E3: 650 | F3: 870
A4: 2 | B4: el/of | C4: b}lgs | D4: 600 | E4: 650 | F4: =F3 -> 870
A5: 3 | B5: l;kfn' sfdbf/-l;sdL{,8sdL{,gsdL{,ah|sdL{, lrq sf/,KnDa/,On]S6«Ll;og,d]s]lgs,Anfi6/, j]N8/_ | C5: b}lgs | D5: 860 | E5: 940 | F5: 1200
A6: 4 | B6: cw{ l;kfn' sfdbf/-l;sdL{,8sdL{,gsdL{, ah|sdL{, lrqsf/,KnDa/, On]S6«Ll;og,d]s]lgs, Anfi6/, j]N8/_ | C6: b}lgs | D6: 735 | E6: 800 | F6: 940
A7: 5 | B7: ;j]{ x]Nk/ | C7: b}lgs | D7: 600 | E7: 800 | F7: 675
A8: 6 | B8: SofDk js{/ | C8: b}lgs | D8: 600 | E8: 800
A9: 7 | B9: SofDk js{/ -gfkL sfo{sf] nflu_ | C9: b}lgs | D9: 625 | E9: 800
A10: 8 | B10: kfn] rf}sLbf/ | C10: b}lgs | D10: 580 | E10: 650 | F10: 710
A11: 9 | B11: d]:t/ | C11: b}lgs | D11: 370 | E11: 450 | F11: 710
A12: 10 | B12: h+hL/bf/ | C12: b}lgs | D12: 630 | E12: 800 | F12: -
A13: 11 | B13: ;'k/efOh/ ;fwf/0f | C13: b}lgs | D13: 400 | E13: 650
A14: 12 | B14: ;8s lgdf{0fsf] nflu ;'k/efO{h/ | C14: b}lgs | D14: 450 | E14: 650
A15: 13 | B15: ;'k/efOh/ -lgdf{0f sfo{sf] nflu_ | C15: b}lgs | D15: 550 | E15: 650
A16: 14 | B16: ;'k/efOh/, lkmN8 cl;:6}06, u}h l/8/, ;}Dkn/ -vl/bf/ ;/x k|fljlws_ | C16: b}lgs | D16: 550 | E16: 800
A17: 15 | B17: ;'k/efOh/ tflnd k|fKt, gf=;' ;/x | C17: b}lgs | D17: 600 | E17: 800 | F17: 1100
A18: 16 | B18: cf}iflw 5g]{ -:k|]o/ _ | C18: b}lgs | D18: 525 | E18: 650
A19: 17 | B19: kmf]/d}g -cf}iflw 5g]{_ | C19: b}lgs | D19: 575 | E19: 650
A20: 18 | B20: ;8s sfnf]kq] ug]{ HofdL | C20: b}lgs | D20: 600 | E20: 800
A21: 19 | B21: sDKo"6/ ck/]6/ -gf=;'= :t/_ | C21: b}lgs | D21: 630 | E21: 800
A22: 20 | B22: sDKo"6/ ck/]6/ -vl/bf/ :t/_ | C22: b}lgs | D22: 550 | E22: 650
A23: 21 | B23: 8«fOe/ -x]eL ;jf/L rfns_ | C23: b}lgs | D23: 600 | E23: 800
A24: 22 | B24: 8«fOe/ -xn'sf ;jf/L rfns_ | C24: b}lgs | D24: 565 | E24: 650
A25: 23 | B25: O{l~hlgo/ -clws[t :t/_ | C25: b}lgs | D25: 1000 | E25: 1100
A26: 24 | B26: ;j—O{l~hlgo/, h]=l6 -gf=;'= :t/_ | C26: b}lgs | D26: 750 | E26: 800 | H26: =800*1.1 -> 880
A27: 25 | B27: c=;a–O{lGhgLo/÷6fOlki6÷h]=l6=P –vl/bf/ :t/ | C27: b}lgs | D27: 680 | E27: 700
A28: 19 | B28: g;{/L gfO{s]÷jg x]/fn' | C28: b}lgs | D28: 525 | E28: 650
A29: 27 | B29: ljleGg ;fOhsf] tf/hfnL–nf]8 ug]{ jf cgnf]8 ug]{ | C29: uf]6f | D29: 11 | E29: 12
A30: 28 | B30: ljleGg u]hsf] tf/–nf]8 ug]{ jf cgnf]8 ug]{ | C30: k|lt %) s]=hL= | D30: 11 | E30: 12
A31: 29 | B31: lhof] a}u–nf]8 ug]{ jf cgnf]8 ug]{ | C31: k|lt !))) yfg | D31: 125 | E31: 125
A32: 30 | B32: gfO{ng qm]6–nf]8 ug]{ jf cgnf]8 ug]{ | C32: uf]6f | D32: 11 | E32: 12
A34: gf]6 M– | B34: !_ o; afx]s cGo kbx?df egf{ u/L Hofnfbf/Ldf sfd nufpFbf h'g kbdf sfd u/fpg] xf], ;f] kbdf g]kfn ;/sf/n] lgwf{/0f u/]sf] z'? tna :s]nnfO{ @% n] efu ubf{ cfpg] /sdnfO b}lgs Hofnf sfod ug]{
B35: @_ sfdbf/sf] sfd ug]{ ;do lbgsf] * 306f x'g]5 .
B36: #_ el/ofn] ! lbgdf $) s]=hL=;Dd ef/L af]sL $ sf]if b"/L ;Dd to ug{' kg]{5 .
B37: $_ lgwf{/0f ul/Psf] b//]6df d"No clej[l4 s/ ;dfj]z ul/Psf] 5}g .

Sheet Aluminium Door-Windows
A1: ='Basic Rate'!A1:H1 -> GOVERNMENT OF NEPAL
A2: ='Basic Rate'!A2:H2 -> RAINAS MUNICIPALITY
A3: ='Basic Rate'!A3:H3 -> OFFICE OF THE MUNICIPAL EXECUTIVE
A4: ='Basic Rate'!A4:H4 -> TINPIPLE,LAMJUNG
A5: ='Basic Rate'!A5:H5 -> 0
A6: Aluminium Door and Window
A8: DISTRICT : RAUTAHAT | G8: F / Y : 2078/79
A9: S. No. | B9: Description | C9: Unit | D9: District Rate | E9: Transportation @ 3 % | F9: Rate | G9: Remark | H9: rate code
A10: 1 | B10: Alluminium fixed panel window With ventilation but without fly mesh shutter from section( 88mmx38.1mm x1.3mm , Glass 5mm) | C10: Sqm. | D10: REF | F10: =D10+E10 -> #VALUE! | G10: Parsa | L10: =484*10.76 -> 5207.84
A11: 2 | B11: Alluminium fixed panel window With Ventilation with fly mesh shutter from section(88mmx38.1mm x1.3mm , Glass 5mm ) | C11: Sqm. | D11: REF | F11: =D11+E11 -> #VALUE! | G11: Parsa
A12: 3 | B12: Alluminium framed Sliding window Without ventilator ( Aluminium :- Natural anodised 101mmx45mm x1.50mm , Glass 5mm clear) | C12: Sqm. | D12: REF | F12: =D12+E12 -> #VALUE! | G12: Parsa
A13: 4 | B13: Alluminium framed Sliding window With ventilator ( Aluminium :- Natural anodised 101mmx45mm x1.5mm , Glass 5mm clear) | C13: Sqm. | D13: REF | F13: =D13+E13 -> #VALUE! | G13: Parsa | K13: =5649/10.76 -> 525
A14: 5 | B14: Alluminium framed Sliding Door ( Aluminium :- Natural anodised 101mmx45mm x1.5mm ,) with sash 40*45*1.5mm and 5mm glass | C14: Sqm. | D14: REF | F14: =D14+E14 -> #VALUE! | G14: Parsa
A15: 6 | B15: Casement double panel aluminium window With ventilator section of ( 54mmx33mm x1.5)mm with sash 38*34*1.5mm with Glass 5mm | C15: Sqm. | D15: REF | F15: =D15+E15 -> #VALUE! | G15: Parsa
A16: 7 | B16: Alluminium Casement Door section of ( 101mmx45mm x1.1)mm sash 40*45*1.1mm & Glass 5mm | C16: Sqm. | D16: REF | F16: =D16+E16 -> #VALUE! | G16: Parsa
A17: 8 | B17: Alluminium framed Swing Door section of (101mmx45mm x1.5)mm & Glass 5mm clear | C17: Sqm. | D17: REF | F17: =D17+E17 -> #VALUE! | G17: Parsa
A18: 9 | B18: Alluminium framed Sliding window 2 track section of (88mmx38mm x1.5)mm & Glass 5mm | C18: Sqm. | D18: REF | F18: =D18+E18 -> #VALUE! | G18: Parsa
A19: 10 | B19: Alluminium fixed window and partition with fixed ventilator from 9mm bord and section (101mmx45mm x1.5)mm | C19: Sqm. | D19: REF | F19: =D19+E19 -> #VALUE! | G19: Parsa
A20: 11 | B20: Alluminium partition with 5mm thick glass & 9mm thick laminated bord of section (101mmx45mm x1.5)mm | C20: Sqm. | D20: REF | F20: =D20+E20 -> #VALUE! | G20: Parsa
A21: 12 | B21: Alluminium partition with 5mm thick glass & 9mm thick laminated bord of section (64mmx38mm x1.1)mm | C21: Sqm. | D21: REF | F21: =D21+E21 -> #VALUE! | G21: Parsa
A22: 13 | B22: False ceiling by Gypsum, Gypsum board 12.5 mm With providing,finisging og joint with compound & tape all complete | C22: Sqm. | D22: REF | F22: =D22+E22 -> #VALUE! | G22: Parsa
A23: 14 | B23: Alluminium fixed panel window With ventilation but without fly mesh shutter from section( 78mmx38.1mm x1.1mm , Glass 4.75 -5mm | C23: Sqm. | D23: REF | F23: =D23+E23 -> #VALUE! | L23: =484*10.76 -> 5207.84
A24: 15 | B24: Alluminium fixed panel window With ventilation but without fly mesh shutter from section( 88mmx38.1mm x1.3mm , Glass 4.75-5mm) | C24: Sqm. | D24: REF | F24: =D24+E24 -> #VALUE! | L24: =484*10.76 -> 5207.84
A25: 16 | B25: Alluminium fixed panel window With Ventilation with fly mesh shutter from section(88mmx38.1mm x1.3mm , Glass 4.75-5mm ) | C25: Sqm. | D25: REF | F25: =D25+E25 -> #VALUE! | L25: =484*10.76 -> 5207.84
A26: 17 | B26: Alluminium framed Sliding window Without ventilator ( Aluminium :- Natural anodised 101mmx45mm x1.50mm , Glass 4.75-5mm clear) | C26: Sqm. | D26: REF | F26: =D26+E26 -> #VALUE! | L26: =484*10.76 -> 5207.84
B27: Pre-cast Structure
B28: 2 Inch Pre stress precast concrete toilet wall and ceiling panel | D28: 523
B29: Pre stress precast concrete benches | D29: 7600
B30: Pre stress precast concrete compound wall | D30: 285
B31: Pre stress precast concrete fencing pole (4"*4") | D31: 133
B32: Pre stress precast concrete fencing pole (5"*5") | D32: 152

Sheet Add Analysis
A1: 8.23 | B1: H21(11-21) | C1: 20 mm thick Sal wood planking work with 50x75 mm sal wood frame in 600x600 mm | F1: Sqm. | G1: =TRUNC(G7/10,2) -> 5312.41 | H1: =TRUNC(G9/10,2) -> 6109.27
B2: Resources | C2: Level/Type | D2: Quantity | E2: Unit | F2: Rate | G2: Amount | H2: Remarks
B3: Labour | C3: Skilled | D3: 6.5 | E3: Nos. | F3: =LOOKUP(C3,'Basic Rate'!$B$8:$B$328,'Basic Rate'!$F$8:$F$328) -> 1200 | G3: =TRUNC(D3*F3,2) -> 7800
C4: Unskilled | D4: 0.65 | E4: Nos. | F4: =LOOKUP(C4,'Basic Rate'!$B$8:$B$328,'Basic Rate'!$F$8:$F$328) -> 870 | G4: =TRUNC(D4*F4,2) -> 565.5
B5: Materials | C5: Wood Sal | D5: =0.421/2 -> 0.2105 | E5: Cum. | F5: =LOOKUP(C5,'Basic Rate'!$B$8:$B$328,'Basic Rate'!$F$8:$F$328) -> 211680 | G5: =TRUNC(D5*F5,2) -> 44558.64
C6: Killa | G6: 200
B7: Rate analysis for :10.00 Sqm. | D7: Total | G7: =SUM(G3:G6) -> 53124.14
D8: 15 % Contractor overhead | G8: =INT(15%*G7*100)/100 -> 7968.62
D9: Grand Total | G9: =SUM(G7:G8) -> 61092.76
A11: 3.18 | B11: C10( 6-5) | C11: Stone filling in trench with proper leveling (Ex.Boulder Used) | F11: Cum. | G11: =G16 -> 1305 | H11: =G18 -> 1500.75
B12: Resources | C12: Level/Type | D12: Quantity | E12: Unit | F12: Rate | G12: Amount | H12: Remarks
B13: Labour | C13: Unskilled | D13: 1.5 | E13: Nos. | F13: =LOOKUP(C13,'Basic Rate'!$B$8:$B$328,'Basic Rate'!$F$8:$F$328) -> 870 | G13: =TRUNC(D13*F13,2) -> 1305
B14: Materials | C14: Stone block | D14: 0 | E14: Cum. | F14: =LOOKUP(C14,'Basic Rate'!$B$8:$B$328,'Basic Rate'!$F$8:$F$328) -> 1910 | G14: =TRUNC(D14*F14,2) -> 0
C15: Stone bond | D15: 0 | E15: Cum. | F15: =LOOKUP(C15,'Basic Rate'!$B$8:$B$328,'Basic Rate'!$F$8:$F$328) -> 1810 | G15: =TRUNC(D15*F15,2) -> 0
B16: Rate analysis for : 1.00 Cum. | D16: Total | G16: =SUM(G13:G15) -> 1305
D17: 15 % Contractor overhead | G17: =INT(15%*G16*100)/100 -> 195.75
D18: Grand Total | G18: =SUM(G16:G17) -> 1500.75
A19: t= Uoflaogsf] sfd
A20: P1 | C20: Gabion making work with wire cutting,weaving,Hexagonal mess size: 80x100mm,mess wire 10 swg selwage wire 9swg,Gabion box (3.0x1.0x0.5 ) & Gabion fixing wearing all complete work. | F20: Per Box | G20: =G28 -> #VALUE! | H20: =G30 -> #VALUE!
B21: Resources | C21: Level/Type | D21: Quantity | E21: Unit | F21: Rate | G21: Amount | H21: Remarks
B22: Labour | C22: Skilled | D22: 0.45 | E22: Nos. | F22: =LOOKUP(C22,'Basic Rate'!$B$8:$B$328,'Basic Rate'!$F$8:$F$328) -> 1200 | G22: =TRUNC(D22*F22,2) -> 540
C23: Unskilled | D23: 0.2 | E23: Nos. | F23: =LOOKUP(C23,'Basic Rate'!$B$8:$B$328,'Basic Rate'!$F$8:$F$328) -> 870 | G23: =TRUNC(D23*F23,2) -> 174
C24: Unskilled | D24: 0.3 | E24: Nos. | F24: =LOOKUP(C24,'Basic Rate'!$B$8:$B$328,'Basic Rate'!$F$8:$F$328) -> 870 | G24: =TRUNC(D24*F24,2) -> 261
B25: Materials | C25: Gavion wire commercial | D25: 30.6 | E25: kgs | F25: ` | G25: =TRUNC(D25*F25,2) -> #VALUE!
C26: Selwage wire 9swg | D26: 3.9 | E26: kgs | F26: 90.64 | G26: =TRUNC(D26*F26,2) -> 353.49
C27: Binding wire 11swg | D27: 1.2 | E27: kgs | F27: 90.64 | G27: =TRUNC(D27*F27,2) -> 108.76
B28: Rate analysis for :10.00 Sqm. | D28: Total | G28: =SUM(G22:G27) -> #VALUE!
D29: 15 % Contractor overhead | G29: =INT(15%*G28*100)/100 -> #VALUE!
D30: Grand Total | G30: =SUM(G28:G29) -> #VALUE!
C32: Supplying & filling of Boulder in Gabion box (3.0x1.0x0.5 ) & Gabion fixing wearing all complete work. | F32: cum | G32: =G37 -> 2345 | H32: =G39 -> 2696.75
B33: Resources | C33: Level/Type | D33: Quantity | E33: Unit | F33: Rate | G33: Amount | H33: Remarks
B34: Labour | C34: Skilled | E34: Nos. | F34: =LOOKUP(C34,'Basic Rate'!$B$8:$B$328,'Basic Rate'!$F$8:$F$328) -> 1200 | G34: =TRUNC(D34*F34,2) -> 0
C35: Unskilled | D35: 0.5 | E35: Nos. | F35: =LOOKUP(C35,'Basic Rate'!$B$8:$B$328,'Basic Rate'!$F$8:$F$328) -> 870 | G35: =TRUNC(D35*F35,2) -> 435
B36: Materials | C36: Stone block | D36: 1 | E36: cum | F36: =LOOKUP(C36,'Basic Rate'!$B$8:$B$328,'Basic Rate'!$F$8:$F$328) -> 1910 | G36: =TRUNC(D36*F36,2) -> 1910
B37: Rate analysis for :10.00 Sqm. | D37: Total | G37: =SUM(G34:G36) -> 2345
D38: 15 % Contractor overhead | G38: =INT(15%*G37*100)/100 -> 351.75
D39: Grand Total | G39: =SUM(G37:G38) -> 2696.75
A40: P1 | C40: u]laog agfpg] sfd . tf/ sf6\g], a'Gg] sfd cflb ;d]t if6sf]0fLo . d]; ;fO{h *) ld=ld=x !)) ld=ld=, d]; tf/ ( P;=8An'=lh=, ;]nj]h tf/ ^ P;=8An'=lh=
C41: @ ld=x ! ld= x ! ld= afs; | D41: k|lt afs; | E41: l;kfn' | F41: ;+Vof | G41: )=%)) | H41: lh=cfO{=tf/
E42: HofdL | F42: ;+Vof | G42: )=@)) | H42: ;]nj]h tf/
...

Sheet LM Collection
C2: Nurms used in this is derieved from DoLIDAR used for Trail bridge
A4: 220 | B4: Local Material Collection
A5: 221 | B5: Chisel Dressed Stones per m3
B6: Labour
B7: Collection and Dressing | C7: Skilled | D7: md | E7: 8 | F7: ='[6]Input Sheet'!#REF! -> #REF! | G7: =E7*F7 -> #REF!
C8: Unskilled | D8: md | E8: 3 | F8: ='[6]Input Sheet'!#REF! -> #REF! | G8: =E8*F8 -> #REF!
B9: Transportation | C9: Tractor ( 17.5qtlX12kmX1.2Rs) | D9: m3 | E9: 1 | G9: =E9*F9 -> 0
B10: Cost per m3 for collecting and chisel dressing stones | G10: =SUM(G7:G9) -> #REF!
A11: 222 | B11: Hammer Dressed Stone per m3
B12: Labour
B13: Collection and Dressing | C13: Skilled | D13: md | E13: 4 | F13: =F7 -> #REF! | G13: =E13*F13 -> #REF!
C14: Unskilled | D14: md | E14: 3 | F14: =F8 -> #REF! | G14: =E14*F14 -> #REF!
B15: Transportation | C15: Tractor ( 17.5qtlX12kmX1.2Rs) | D15: m3 | E15: 1 | G15: =E15*F15 -> 0
B16: Cost per m3 for collecting and hammer dressing stones | G16: =SUM(G13:G15) -> #REF!
A17: 223 | B17: Broken Stones per m3
B18: Labour
B19: Collection and breaking | C19: Unskilled | D19: md | E19: 5 | F19: 480 | G19: =E19*F19 -> 2400
B20: Transportation | C20: Truck (1truck=m3) | D20: m3 | E20: 1 | G20: =E20*F20 -> 0
B21: Cost per m3 for collecting and breaking stones | G21: =SUM(G19:G20) -> 2400
A23: 1 Apply District Rates
A26: COST ESTIMATE: | G26: Rate Analysis (page 3)
A28: Description | D28: Unit | E28: Unit Quantity | F28: Rate1 | G28: Unit Cost
A29: 224 | B29: Sand pe m3
B30: Labour | C30: Unskilled | D30: md | E30: 3 | F30: =F8 -> #REF! | G30: =E30*F30 -> #REF!
B31: Transportation | C31: Tractor ( 17.5qtlX60kmX1.2Rs) | D31: m3 | E31: 1 | G31: =E31*F31 -> 0
B32: Cost per m3 for collecting and hauling sand | G32: =SUM(G30:G31) -> #REF!
A33: 225 | B33: Gravel (Broken)
B34: Labour Breaking of gravel | C34: Unskilled | D34: md | E34: 7 | F34: =F8 -> #REF! | G34: =E34*F34 -> #REF!
B35: Transportation | C35: Truck (1truck=m3) | D35: m3 | E35: 1 | G35: =E35*F35 -> 0
B36: Cost per m3 for breaking gravel | G36: =SUM(G34:G35) -> #REF!

Sheet Cover1
A1: g]kfn ;/sf/
A2: zx/L ljsf; dGqfno
A3: zx/L ljsf; tyf ejg lgdf{0f ljefu
A4: ;+3Lo cfof]hgf sfof{Gjog OsfO{
A5: hgsk'/wfd, wg'iff
A6: b/ ljZn]if0f, wg'iff
A8: l;len
A11: cf=j= @)&*÷)&(
A13: tof/ ug]{ M–
A15: r]s hfFr ug]{ M–
A18: k|dfl0ft ug]{ M–
A21: ldlt M–

Sheet add
A1: 15.03 | B1: O3(15-9A) | C1: sub base laying work with sand mixed gravel, load unload & proper levelling. | F1: Sqm. | G1: =TRUNC(G5,2) -> 2474 | H1: =TRUNC(G7,2) -> 2845.1
B2: Resources | C2: Level/Type | D2: Quantity | E2: Unit | F2: Rate | G2: Amount | H2: Remarks
B3: Labours | C3: Unskilled | D3: 1.2 | E3: Nos. | F3: =LOOKUP(C3,'Basic Rate'!$B$8:$B$328,'Basic Rate'!$F$8:$F$328) -> 870 | G3: =INT(D3*F3*100)/100 -> 1044
B4: Material | C4: Sand mixed gravel | D4: 1 | E4: Cum. | F4: =LOOKUP(C4,'Basic Rate'!$B$8:$B$328,'Basic Rate'!$F$8:$F$328) -> 1430 | G4: =INT(D4*F4*100)/100 -> 1430
B5: Rate analysis for : 1.00Cum | D5: Total | G5: =SUM(G3:G4) -> 2474
D6: 15 % Contractor overhead | G6: =INT(15%*G5*100)/100 -> 371.1
D7: Grand Total | G7: =SUM(G5:G6) -> 2845.1
A11: 4.03 | B11: D1(7-2D) | C11: P.C.C. (1:2:4) Plum supply of matarials hulage distance all complete. work in foundation, wall (River bed) | F11: Cum. | G11: =G19 -> 11167.7 | H11: =G21 -> 12842.85
B12: Resources | C12: Level/Type | D12: Quantity | E12: Unit | F12: Rate | G12: Amount | H12: Remarks
B13: Labour | C13: Skilled | D13: 0.5 | E13: Nos. | F13: =LOOKUP(C13,'Basic Rate'!$B$8:$B$328,'Basic Rate'!$F$8:$F$328) -> 1200 | G13: =TRUNC(D13*F13,2) -> 600
C14: Unskilled | D14: 4 | E14: Nos. | F14: =LOOKUP(C14,'Basic Rate'!$B$8:$B$328,'Basic Rate'!$F$8:$F$328) -> 870 | G14: =TRUNC(D14*F14,2) -> 3480
B15: Materials | C15: Cement | D15: 0.32 | E15: M.T. | F15: =LOOKUP(C15,'Basic Rate'!$B$8:$B$328,'Basic Rate'!$F$8:$F$328) -> 14000 | G15: =TRUNC(D15*F15,2) -> 4480 | I15: =320/50 -> 6.4
C16: Aggrigate 40 mm-River bed & Stone block | D16: 0.89 | E16: Cum. | F16: =LOOKUP(C16,'Basic Rate'!$B$8:$B$328,'Basic Rate'!$F$8:$F$328) -> 1830 | G16: =TRUNC(D16*F16,2) -> 1628.7
C17: Sand | D17: 0.445 | E17: Cum. | F17: ='Basic Rate'!F173 -> 2200 | G17: =TRUNC(D17*F17,2) -> 979
C18: Water | D18: 150 | E18: Ltr. | F18: =LOOKUP(C18,'Basic Rate'!$B$8:$B$328,'Basic Rate'!$F$8:$F$328) -> 0 | G18: =TRUNC(D18*F18,2) -> 0
B19: Rate analysis for : 1.00 Cum. | D19: Total | G19: =SUM(G13:G18) -> 11167.7
D20: 15 % Contractor overhead | G20: =INT(15%*G19*100)/100 -> 1675.15
D21: Grand Total | G21: =SUM(G19:G20) -> 12842.85

Sheet HDP,Pipe,Rate
A4: Price List of HDPE Pipe
A6: F.Y. : 078/79
A8: S.No. | B8: Pipe size (Outer side Ø mm) | C8: Series II 2.5Kg/sqcm | E8: Series III 4Kg/sqcm | G8: Series IV 6Kg/sqcm | I8: Series V 10Kg/sqcm | K8: Contractor Rate | L8: Pipe size (Outer side Ø mm)
C9: Ave.Wt. kg/m | D9: Price Rs./m | E9: Ave.Wt. kg/m | F9: Price Rs./m | G9: Ave.Wt. kg/m | H9: Price Rs./m | I9: Ave.Wt. kg/m | J9: Price Rs./m
A10: 1 | B10: 16mm | C10: – | D10: – | E10: – | F10: – | G10: – | H10: – | I10: 0.092 | J10: =I10*$D$40*1.04 -> 28.89536 | K10: =J10*0.15+J10 -> 33.229664 | L10: 1/2"
A11: 2 | B11: 20mm | C11: – | D11: – | E11: – | F11: – | G11: – | H11: – | I11: 0.134 | J11: =I11*$D$40*1.04 -> 42.08672 | K11: =J11*0.15+J11 -> 48.399728 | L11: 3/4"
A12: 3 | B12: 25mm | C12: – | D12: – | E12: – | F12: – | G12: – | H12: – | I12: 0.202 | J12: =I12*$D$40*1.04 -> 63.44416 | K12: =J12*0.15+J12 -> 72.960784 | L12: 1"
A13: 4 | B13: 32mm | C13: – | D13: – | E13: – | F13: – | G13: 0.226 | H13: =G13*260*1.04 -> 61.1104 | I13: 0.334 | J13: =I13*$D$40*1.04 -> 104.90272 | K13: =J13*0.15+J13 -> 120.63813 | L13: 1-1/4"
A14: 5 | B14: 40mm | C14: – | D14: – | E14: 0.251 | F14: =E14*260*1.04 -> 67.8704 | G14: 0.35 | H14: =G14*260 -> 91 | I14: 0.514 | J14: =I14*$D$40*1.04 -> 161.43712 | K14: =J14*0.15+J14 -> 185.65269 | L14: 1-1/2"
A15: 6 | B15: 50mm | C15: – | D15: – | E15: 0.378 | F15: =E15*260*1.04 -> 102.2112 | G15: 0.542 | H15: =G15*260 -> 140.92 | I15: 0.796 | J15: =I15*$D$40*1.04 -> 250.00768 | K15: =J15*0.15+J15 -> 287.50883 | L15: 2"
A16: 7 | B16: 63mm | C16: 0.403 | D16: =C16*260*1.04 -> 108.9712 | E16: 0.585 | F16: =E16*260*1.04 -> 158.184 | G16: 0.85 | H16: =G16*260 -> 221 | I16: 1.269 | J16: =I16*$D$40*1.04 -> 398.56752 | K16: =J16*0.15+J16 -> 458.35265 | L16: 2-1/2"
A17: 8 | B17: 75mm | C17: 0.557 | D17: =C17*260*1.04 -> 150.6128 | E17: 0.846 | F17: =E17*260*1.04 -> 228.7584 | G17: 1.191 | H17: =G17*260 -> 309.66 | I17: 1.782 | J17: =I17*$D$40*1.04 -> 559.69056 | K17: =J17*0.15+J17 -> 643.64414 | L17: 3"
A18: 9 | B18: 90mm | C18: 0.799 | D18: =C18*260*1.04 -> 216.0496 | E18: 1.22 | F18: =E18*260*1.04 -> 329.888 | G18: 1.715 | H18: =G18*260 -> 445.9 | I18: 2.568 | J18: =I18*$D$40*1.04 -> 806.55744 | K18: =J18*0.15+J18 -> 927.54106 | L18: 3-1/2"
A19: 10 | B19: 110mm | C19: 1.185 | D19: =C19*260*1.04 -> 320.424 | E19: 1.703 | F19: =E19*260*1.04 -> 460.4912 | G19: 2.545 | H19: =G19*260 -> 661.7 | I19: 3.801 | J19: =I19*$D$40*1.04 -> 1193.8181 | K19: =J19*0.15+J19 -> 1372.8908 | L19: 4"
A20: 11 | B20: 125mm | C20: 1.53 | D20: =C20*260*1.04 -> 413.712 | E20: 2.289 | F20: =E20*260*1.04 -> 618.9456 | G20: 3.293 | H20: =G20*260 -> 856.18 | I20: 4.962 | J20: =I20*$D$40*1.04 -> 1558.465 | K20: =J20*0.15+J20 -> 1792.2347 | L20: 4-1/2"
A21: 12 | B21: 140mm | C21: 1.897 | D21: =C21*260*1.04 -> 512.9488 | E21: 2.901 | F21: =E21*260*1.04 -> 784.4304 | G21: 4.15 | H21: =G21*260 -> 1079 | I21: 6.209 | J21: =I21*$D$40*1.04 -> 1950.1227 | K21: =J21*0.15+J21 -> 2242.6411 | L21: 5"
A22: 13 | B22: 160mm | C22: 2.453 | D22: =C22*260*1.04 -> 663.2912 | E22: 3.773 | F22: =E22*260*1.04 -> 1020.2192 | G22: 5.355 | H22: =G22*260 -> 1392.3 | I22: 8.079 | J22: =I22*$D$40*1.04 -> 2537.4523 | K22: =J22*0.15+J22 -> 2918.0702 | L22: 6"
A23: 14 | B23: 180mm | C23: 3.148 | D23: =C23*260*1.04 -> 851.2192 | E23: 4.762 | F23: =E23*260*1.04 -> 1287.6448 | G23: 6.8 | H23: =G23*260 -> 1768 | I23: 10.256 | J23: =I23*$D$40*1.04 -> 3221.2045 | K23: =J23*0.15+J23 -> 3704.3852 | L23: 7"
A24: 15 | B24: 200mm | C24: 3.876 | D24: =C24*260*1.04 -> 1048.0704 | E24: 5.89 | F24: =E24*260*1.04 -> 1592.656 | G24: 8.391 | H24: =G24*260 -> 2181.66 | I24: 12.62 | J24: =I24*$D$40*1.04 -> 3963.6896 | K24: =J24*0.15+J24 -> 4558.243 | L24: 8"
A25: 16 | B25: 225mm | C25: 4.822 | D25: =C25*260*1.04 -> 1303.8688 | E25: 7.445 | F25: =E25*260*1.04 -> 2013.128 | G25: 10.544 | H25: =G25*260 -> 2741.44 | I25: 16.014 | J25: =I25*$D$40*1.04 -> 5029.6771 | K25: =J25*0.15+J25 -> 5784.1287 | L25: 9"
A26: 17 | B26: 250mm | C26: 6.012 | D26: =C26*260*1.04 -> 1625.6448 | E26: 9.187 | F26: =E26*260*1.04 -> 2484.1648 | G26: 13.041 | H26: =G26*260 -> 3390.66 | I26: 19.757 | J26: =I26*$D$40*1.04 -> 6205.2786 | K26: =J26*0.15+J26 -> 7136.0703 | L26: 10"
A27: 18 | B27: 280mm | C27: 7.417 | D27: =C27*260*1.04 -> 2005.5568 | E27: 11.455 | F27: =E27*260*1.04 -> 3097.432 | G27: 16.327 | H27: =G27*260 -> 4245.02 | I27: 24.708 | J27: =I27*$D$40*1.04 -> 7760.2886 | K27: =J27*0.15+J27 -> 8924.3319 | L27: 11"
... A30: 21 | B30: 400mm | C30: 15.221 | D30: =C30*260*1.04 -> 4115.7584 | E30: 23.343 | F30: =E30*260*1.04 -> 6311.9472 | G30: 33.309 | H30: =G30*260 -> 8660.34 | I30: 50.344 | J30: =I30*$D$40*1.04 -> 15812.044 | K30: =J30*0.15+J30 -> 18183.85 | L30: 400mm
A34: Notes :
A35: 1 | B35: Prices are based on ex–factory.
A36: 2 | B36: The above value include all GOV. Taxes except VAT which will be charged extra 13 %
A37: 3 | B37: All pipes are manufactured as NS–40
A38: 4 | B38: Rate of HDPE Pipes Based on Rs. 302.00 Per Kg.
A39: 5 | B39: Add 3% Transportation Charge.
B40: HDPE Rate per kg | D40: 302

Sheet Sheet1

Sheet aluminium dw
A1: =cover!A1 -> GOVERNMENT OF NEPAL
A2: =cover!A2 -> RAINAS MUNICIPALITY
A3: =cover!A3 -> OFFICE OF THE MUNICIPAL EXECUTIVE
A4: =cover!A4 -> TINPIPLE,LAMJUNG
A5: =cover!A5 -> 0
A6: Aluminium Door and Window
A7: DISTRICT : BARA | G7: =Summary!E6 -> F / Y : 2082/083
A8: S. No. | B8: Description | C8: Unit | D8: District Rate | E8: Transportation @ 3 % | F8: Rate | G8: Remark
A9: 1 | B9: Providing and fixing Single Panel Casement (Hinged) Door of aluminium section in natural or color anodized/powder coated color Section size (102x45x1.5 mm) fitted with 5 mm clear glass or 9 mm both side laminated board (excluding the cost of handle and door closer). | C9: Sqm. | D9: =689*10.76 -> 7413.64 | F9: =D9+E9 -> 7413.64 | G9: ktm pg-32(1) 102 series window
A10: 2 | B10: Providing and fixing Double Panel Casement (Hinged) Door of aluminium section in natural or color anodized/powder coated color Section size (102x45x1.5 mm) fitted with 5 mm clear glass or 9 mm both side laminated board (excluding the cost of handle and door closer). | C10: Sqm. | D10: =759*10.76 -> 8166.84 | F10: =D10+E10 -> 8166.84 | G10: ktm pg-32(2) 102 series window
A11: 3 | B11: Providing and fixing Single Panel Swing Door of aluminium section in natural or color anodized/powder coated color Section size (102x45x1.5 mm) fitted with 5 mm clear glass or 9 mm both side laminated board (excluding the cost of handle and door closer). | C11: Sqm. | D11: =877*10.76 -> 9436.52 | F11: =D11+E11 -> 9436.52 | G11: ktm pg-32(3) 102 series window
A12: 4 | B12: Providing and fixing Double Panel Swing Door of aluminium section in natural or color anodized/powder coated color Section size (102x45x1.5 mm) fitted with 5 mm clear glass or 9 mm both side laminated board (excluding the cost of handle and door closer). | C12: Sqm. | D12: =966*10.76 -> 10394.16 | F12: =D12+E12 -> 10394.16 | G12: ktm pg-32(4) 102 series window
A13: 5 | B13: Providing and fixing 2 or 3 Panel Sliding Window of aluminium section in naturally anodized or Black anodized/powder coaded color, Section size (87x56x1.2) fitted with 5 mm clear glass without fly mesh shutter.(window size 6'x5' or average area 30 sq. feet per window). | C13: Sqm. | D13: =550*10.76 -> 5918 | F13: =D13+E13 -> 5918 | G13: ktm pg-32(1) 90 series window
A14: 6 | B14: Providing and fixing 2 or 3 Panel Sliding Window of aluminium section in naturally anodized or Black anodized/powder coaded color, Section size (87x56x1.5) fitted with 5 mm clear glass without fly mesh shutter.(window size 6'x5' or average area 30 sq. feet per window). | C14: Sqm. | D14: =634*10.76 -> 6821.84 | F14: =D14+E14 -> 6821.84 | G14: ktm pg-33(2) 90 series window
A15: 7 | B15: Providing and fixing 2 or 3 Panel Sliding Window with top fix glass of aluminium section in naturally anodized or Black anodized/powder coated color, Section size (87x56x1.20) fitted with 5 mm clear glass without fly mesh shutter.(window size 6'x5' or average area 30 sq. feet per window). | C15: Sqm. | D15: =599*10.76 -> 6445.24 | F15: =D15+E15 -> 6445.24 | G15: ktm pg-33(3) 90 series window
A16: 8 | B16: Providing and fixing 2 or 3 Panel Sliding Window with top fix glass of aluminium section in naturally anodized or Black anodized/powder coated color, Section size (87x56x1.50) fitted with 5 mm clear glass without fly mesh shutter.(window size 6'x5' or average area 30 sq. feet per window). | C16: Sqm. | D16: =690*10.76 -> 7424.4 | F16: =D16+E16 -> 7424.4 | G16: ktm pg-33(4) 90 series window
A17: 9 | B17: Providing and fixing Fixed Window of aluminium section in naturally anodized or Black anodized/powder coated color, Section size (87x25+12x1.20) fitted with 5 mm clear glass without fly mesh shutter.(Average area 5 sq. feet per Panel). | C17: Sqm. | D17: =456*10.76 -> 4906.56 | F17: =D17+E17 -> 4906.56 | G17: ktm pg-33(5) 90 series window
A18: 10 | B18: Providing and fixing Fixed Window of aluminium section in naturally anodized or Black anodized/powder coated color, Section size (87x25+12x1.50) fitted with 5 mm clear glass with out fly mesh shutter.(Average area 5 sq. feet per Panel). | C18: Sqm. | D18: =524*10.76 -> 5638.24 | F18: =D18+E18 -> 5638.24 | G18: ktm pg-33(6) 90 series window
A19: 11 | B19: Providing and fixing Fly Mesh Shutter with stainless steel fly mesh in 90 series for sliding window.(Section thickness 1 mm) | C19: Sqm. | D19: =200*10.76 -> 2152 | F19: =D19+E19 -> 2152 | G19: ktm pg-33(7) 90 series window
A20: 12 | B20: Providing and fixing Full Height Partition of aluminium section in naturally anodized or black anodized/powder coated color section size (102x45x1.5) fitted with 5 mm clear glass or 9 mm both side laminated board.(average panel area 8.00 Sq.ft) | C20: Sqm. | D20: =553*10.76 -> 5950.28 | F20: =D20+E20 -> 5950.28 | G20: ktm pg-33(1) 102 series partition
A21: 13 | B21: Providing and fixing Half Height Partition of aluminium section in naturally anodized or black anodized/powder coated color section size (102x45x1.5) fitted with 5 mm clear glass or 9 mm both side laminated board.(average panel area 6.00 Sq.ft) | C21: Sqm. | D21: =600*10.76 -> 6456 | F21: =D21+E21 -> 6456 | G21: ktm pg-33(2) 102 series partition
A22: 14 | B22: Providing and fixing Full Height Partition of aluminium section in naturally anodized or black anodized/powder coated color section size (64x38x1.10mm) fitted with 5 mm clear glass or 9 mm both side laminated board.(average panel area 8.00 Sq.ft) | C22: Sqm. | D22: =415*10.76 -> 4465.4 | F22: =D22+E22 -> 4465.4 | G22: ktm pg-33(1) 64 series partition
A23: 15 | B23: Providing and fixing Half Height Partition of aluminium section in naturally anodized or black anodized/powder coated color section size (64x38x1.10mm) fitted with 5 mm clear glass or 9 mm both side laminated board.(average panel area 6.00 Sq.ft) | C23: Sqm. | D23: =509*10.76 -> 5476.84 | F23: =D23+E23 -> 5476.84 | G23: ktm pg-33(2) 64 series partition
A24: 16 | B24: False ceiling by Gypsum, Gypsum board 12 mm With providing,finisging og joint with compound & tape all complete | C24: Sqm. | D24: 1400 | F24: =D24+E24 -> 1400 | G24: 10-412
